Workbook

Sheet Cover
B4: NASDAQ: TSLA
B6: TESLA, INC.
B7: FINANCIAL MODEL & VALUATION
B10: Integrated Financial Model | FY2021A – FY2030E
B11: DCF | Trading Comparables | Precedent Transactions
B13: MODEL PROFILE
B14: PREPARED BY | D14: Yash Andhrutkar
B15: MODEL PERIOD | D15: FY2021A – FY2030E (5 historical years, 5 forecast years)
B16: CURRENCY & UNITS | D16: USD millions, except per-share and operating data
B17: HISTORICAL SOURCE | D17: Tesla, Inc. SEC filings, FY2021–FY2025
B18: MARKET DATA | D18: 3 September 2026 close
B19: LAST UPDATED | D19: 46272
B21: NAVIGATION
B22: → Model Summary | D22: KPIs, revenue mix, margins, FCFF, football field, scenario strip
B23: → Assumptions | D23: Every driver, its rationale and the Bear/Base/Bull grids
B24: → Scenario Analysis | D24: Bear, Base and Bull built in parallel from one model
B25: → Valuation | D25: DCF, WACC × TGR sensitivity, exit-multiple and beta cross-checks
B26: → Reverse DCF | D26: What the market price would require
B27: → Sources & Notes | D27: Every external input, with its source
B30: Academic / portfolio financial model. Historical figures are taken from Tesla, Inc. SEC filings; FY2026E–FY2030E figures are the author's own forecasts. Trading comparables are priced at the 3 September 2026 close. This workbook is not investment advice and no recommendation is made to any person to buy or sell any security.

Sheet Model Summary
B1: TESLA, INC. · MODEL SUMMARY | M1: ="NASDAQ: TSLA | FY2021A–FY2030E | SELECTED CASE: "&UPPER(CHOOSE(Assumptions!$L$2,"Bear","Base","Bull")) -> NASDAQ: TSLA | FY2021A–FY2030E | SELECTED CASE: BASE
B3: Integrated three-statement model · driver-based forecast · DCF and trading-comparables valuation · all figures link live to the model
B6: FY2030E REVENUE | G6: FY2030E EBIT MARGIN | L6: DCF IMPLIED VALUE / SHARE | Q6: WACC
B7: =IS!P8 -> 161408.21 | G7: =IS!P26 -> 0.1274056 | L7: =Valuation!K56 -> 32.569468 | Q7: =Valuation!F17 -> 0.12380656
B8: ="FY2025A–FY2030E CAGR "&TEXT((IS!P8/IS!K8)^(1/5)-1,"0.0%") -> FY2025A–FY2030E CAGR 11.2% | G8: ="from "&TEXT(IS!K26,"0.0%")&" in FY2025A" -> from 4.6% in FY2025A | L8: ="Sensitivity "&TEXT(Valuation!E84,"$0.00")&" – "&TEXT(Valuation!I84,"$0.00") -> Sensitivity $26.18 – $45.82 | Q8: ="CAPM · beta "&TEXT(Assumptions!G59,"0.00")&" · TGR "&TEXT(Valuation!F18,"0.0%") -> CAPM · beta 1.85 · TGR 3.8%
B10: CURRENT MARKET PRICE | G10: COMPARABLE COS. BASE VALUE | L10: FY2025A–FY2030E REVENUE CAGR | Q10: TERMINAL GROWTH RATE
B11: =Valuation!G87 -> 376.37 | G11: =Valuation!G85 -> 36.78365 | L11: =(IS!P8/IS!K8)^(1/5)-1 -> 0.11224055 | Q11: =Valuation!F18 -> 0.038
B12: "3 September 2026 close" | G12: ="Range "&TEXT(Valuation!E85,"$0.00")&" – "&TEXT(Valuation!I85,"$0.00") -> Range $30.27 – $51.77 | L12: ="$"&TEXT(IS!K8,"#,##0")&"M → $"&TEXT(IS!P8,"#,##0")&"M" -> $94,827M → $161,408M | Q12: ="Terminal value = "&TEXT(Valuation!K47,"0%")&" of enterprise value" -> Terminal value = 78% of enterprise value
L46: ="Football field: market-price bar runs off the plot area — the axis is capped at $60 so the "&"DCF and comparable ranges keep full resolution. Market price = "&TEXT(Valuation!G87,"$0.00")&"." -> Football field: market-price bar runs off the plot area — the axis is capped at $60 so the DCF and comparable ranges keep full resolution. Market price = $376.37.
B47: VALUATION SUMMARY — IMPLIED SHARE PRICE | L47: MODEL INTEGRITY & KEY OUTPUTS
B48: Method | G48: Low | H48: Base | I48: High | J48: vs. market | L48: Balance sheet check, FY2021A–FY2030E | R48: ='Model Checks'!E6 -> PASS
B49: Discounted Cash Flow | G49: =Valuation!E84 -> 26.184574 | H49: =Valuation!G84 -> 32.569468 | I49: =Valuation!I84 -> 45.82243 | J49: =Valuation!G84/Valuation!$G$87-1 -> -0.91346423 | L49: Cash check, FY2021A–FY2030E | R49: ='Model Checks'!E7 -> PASS
B50: Comparable Companies | G50: =Valuation!E85 -> 30.271642 | H50: =Valuation!G85 -> 36.78365 | I50: =Valuation!I85 -> 51.770477 | J50: =Valuation!G85/Valuation!$G$87-1 -> -0.90226732 | L50: WACC > terminal growth | R50: ='Model Checks'!E11 -> PASS
B51: Current Market Price | G51: – | H51: =Valuation!G87 -> 376.37 | I51: – | J51: – | L51: All model checks (see Model Checks sheet) | R51: ='Model Checks'!E18 -> PASS
B53: SCENARIO VALUATION — ONE INTEGRATED MODEL, THREE CASES
B54: Case | E54: FY30E revenue | G54: FY30E EBIT margin | H54: FY30E FCFF | I54: Enterprise value | J54: Equity value | L54: DCF $/share | M54: vs. market | N54: Scenario character
B55: Bear | E55: ='Scenario Analysis'!G6 -> 113105.54 | G55: ='Scenario Analysis'!G11 -> 0.060189657 | H55: ='Scenario Analysis'!G13 -> 2369.8931 | I55: ='Scenario Analysis'!G14 -> 16863.276 | J55: ='Scenario Analysis'!G15 -> 51818.276 | L55: ='Scenario Analysis'!G16 -> 13.118551 | M55: ='Scenario Analysis'!G17 -> -0.96514454 | N55: Slower deliveries, sustained pricing pressure, weaker margin recovery, higher capex
B56: Base | E56: ='Scenario Analysis'!I6 -> 161408.21 | G56: ='Scenario Analysis'!I11 -> 0.1274056 | H56: ='Scenario Analysis'!I13 -> 10815 | I56: ='Scenario Analysis'!I14 -> 93694.398 | J56: ='Scenario Analysis'!I15 -> 128649.4 | L56: ='Scenario Analysis'!I16 -> 32.569468 | M56: ='Scenario Analysis'!I17 -> -0.91346423 | N56: Current fundamental forecast
B57: Bull | E57: ='Scenario Analysis'!K6 -> 206513.16 | G57: ='Scenario Analysis'!K11 -> 0.17008755 | H57: ='Scenario Analysis'!K13 -> 20083.529 | I57: ='Scenario Analysis'!K14 -> 176169.41 | J57: ='Scenario Analysis'!K15 -> 211124.41 | L57: ='Scenario Analysis'!K16 -> 53.449218 | M57: ='Scenario Analysis'!K17 -> -0.85798757 | N57: Stronger volume and mix, faster Energy scaling, full operating leverage
B59: ="Selected case: "&UPPER(CHOOSE(Assumptions!$L$2,"Bear","Base","Bull"))&". Modelled fundamentals imply "&TEXT(Valuation!K56,"$0.00")&" per share on the DCF and "&TEXT(Valuation!G85,"$0.00")&" on trading comparables, against a market price of "&TEXT(Valuation!G87,"$0.00")&". Across Bear to Bull the DCF spans "&TEXT('Scenario Analysis'!G16,"$0.00")&" to "&TEXT('Scenario Analysis'!K16,"$0.00")&", so the gap to the market price is not a scenario question. The Reverse DCF sheet shows what the market price would require: roughly "&TEXT('Reverse DCF'!F61,"0.0")&"x the Base Case FY2030E free cash flow." -> Selected case: BASE. Modelled fundamentals imply $32.57 per share on the DCF and $36.78 on trading comparables, against a market price of $376.37. Across Bear to Bull the DCF spans $13.12 to $53.45, so the gap to the market price is not a scenario question. The Reverse DCF sheet shows what the market price would require: roughly 15.7x the Base Case FY2030E free cash flow.
B61: Every figure and chart on this sheet is linked live to the model. Chart sources — revenue mix: IS!G5:P7 · margins: 'Ratio Analysis'!I40:R47 · FCFF: Valuation!L28:P28 · football field: Valuation!C91:F93. Scenario strip: 'Scenario Analysis'!G6:K17.

Sheet Assumptions
A1: TESLA, INC. | E1: ◄ Cover | G1: ASSUMPTIONS | AA1: HELPER COLUMN — full text of every forecast rationale, kept here so the wording stays auditable and searchable. The user-facing version is displayed in the callout boxes beside each assumption block. Column is hidden by default.
A2: USD millions except per-share and operating data · Blue = input · Black = same-sheet formula · Green = cross-sheet link · Shaded = scenario-driven | K2: SCENARIO ▸ | L2: 2 | M2: =CHOOSE($L$2,"Bear","Base","Bull") -> Base | N2: =CHOOSE($L$2,"case — downside operating environment","case — current fundamental forecast","case — strong but defensible execution") -> case — current fundamental forecast
E3: Unit | G3: FY21A | H3: FY22A | I3: FY23A | J3: FY24A | K3: FY25A | L3: FY26E | M3: FY27E | N3: FY28E | O3: FY29E | P3: FY30E
Q4: FORECAST RATIONALE (FY2026E – FY2030E)
A5: AUTOMOTIVE | AA5: AUTOMOTIVE | Vehicle deliveries — recovery from 1.64m in FY2025A to 2.54m by FY2030E, a 9.2% CAGR (+6%, +10%, +12%, +10%, +8%). Growth is rebuilt gradually rather than extrapolated from the FY2021–FY2023 ramp. ASP per delivery — (3.0%), (2.0%), then +1.0%, +1.0%, +2.0%. Pricing stays under competitive pressure near term before stabilising, so the forecast never relies on unit growth alone. Regulatory credits — declining 30%, 20%, 10%, 5%, 5% as other OEMs meet emissions rules from their own fleets — treated as a wasting revenue stream, not a perpetual one. Automotive gross margin — 19.0% rising to 23.0%: a partial recovery from the depressed FY2025A level on scale and manufacturing cost, deliberately held below the FY2022 peak.
C6: Vehicle Deliveries (context) | E6: units | G6: ='Revenue Build-up'!G5 -> 936172 | H6: ='Revenue Build-up'!H5 -> 1313851 | I6: ='Revenue Build-up'!I5 -> 1808581 | J6: ='Revenue Build-up'!J5 -> 1789226 | K6: ='Revenue Build-up'!K5 -> 1636129 | L6: ='Revenue Build-up'!L5 -> 1734296.7 | M6: ='Revenue Build-up'!M5 -> 1907726.4 | N6: ='Revenue Build-up'!N5 -> 2136653.6 | ... P6: ='Revenue Build-up'!P5 -> 2538344.5
C7: Delivery Growth % | H7: ='Revenue Build-up'!H5/'Revenue Build-up'!G5-1 -> 0.40342907 | I7: ='Revenue Build-up'!I5/'Revenue Build-up'!H5-1 -> 0.37654955 | J7: ='Revenue Build-up'!J5/'Revenue Build-up'!I5-1 -> -0.01070176 | K7: ='Revenue Build-up'!K5/'Revenue Build-up'!J5-1 -> -0.085566049 | L7: =CHOOSE($L$2,L68,L69,L70) -> 0.06 | M7: =CHOOSE($L$2,M68,M69,M70) -> 0.1 | N7: =CHOOSE($L$2,N68,N69,N70) -> 0.12 | O7: =CHOOSE($L$2,O68,O69,O70) -> 0.1 | P7: =CHOOSE($L$2,P68,P69,P70) -> 0.08
C9: Automotive Revenue per Delivery (context) | E9: $/unit | G9: ='Revenue Build-up'!G6 -> 48887.384 | H9: ='Revenue Build-up'!H6 -> 53039.5 | I9: ='Revenue Build-up'!I6 -> 44581.36 | J9: ='Revenue Build-up'!J6 -> 41530.248 | K9: ='Revenue Build-up'!K6 -> 41276.085 | L9: ='Revenue Build-up'!L6 -> 40037.803 | M9: ='Revenue Build-up'!M6 -> 39237.047 | N9: ='Revenue Build-up'!N6 -> 39629.417 | ... P9: ='Revenue Build-up'!P6 -> 40826.225
C10: ASP Growth % | H10: ='Revenue Build-up'!H6/'Revenue Build-up'!G6-1 -> 0.084932259 | I10: ='Revenue Build-up'!I6/'Revenue Build-up'!H6-1 -> -0.1594687 | J10: ='Revenue Build-up'!J6/'Revenue Build-up'!I6-1 -> -0.068439173 | K10: ='Revenue Build-up'!K6/'Revenue Build-up'!J6-1 -> -0.0061199508 | L10: =CHOOSE($L$2,L71,L72,L73) -> -0.03 | M10: =CHOOSE($L$2,M71,M72,M73) -> -0.02 | N10: =CHOOSE($L$2,N71,N72,N73) -> 0.01 | O10: =CHOOSE($L$2,O71,O72,O73) -> 0.01 | P10: =CHOOSE($L$2,P71,P72,P73) -> 0.02
C11: Automotive Regulatory Credits (context) | E11: $M | G11: ='Revenue Build-up'!G8 -> 1465 | H11: ='Revenue Build-up'!H8 -> 1776 | I11: ='Revenue Build-up'!I8 -> 1790 | J11: ='Revenue Build-up'!J8 -> 2763 | K11: ='Revenue Build-up'!K8 -> 1993 | L11: ='Revenue Build-up'!L8 -> 1395.1 | M11: ='Revenue Build-up'!M8 -> 1116.08 | N11: ='Revenue Build-up'!N8 -> 1004.472 | ... P11: ='Revenue Build-up'!P8 -> 906.53598
C12: Regulatory Credit Revenue Growth % | H12: ='Revenue Build-up'!H8/'Revenue Build-up'!G8-1 -> 0.21228669 | I12: ='Revenue Build-up'!I8/'Revenue Build-up'!H8-1 -> 0.0078828829 | J12: ='Revenue Build-up'!J8/'Revenue Build-up'!I8-1 -> 0.54357542 | K12: ='Revenue Build-up'!K8/'Revenue Build-up'!J8-1 -> -0.27868259 | L12: =CHOOSE($L$2,L74,L75,L76) -> -0.3 | M12: =CHOOSE($L$2,M74,M75,M76) -> -0.2 | N12: =CHOOSE($L$2,N74,N75,N76) -> -0.1 | O12: =CHOOSE($L$2,O74,O75,O76) -> -0.05 | P12: =CHOOSE($L$2,P74,P75,P76) -> -0.05
C14: Automotive Gross Margin % | G14: ='Cost Build-up'!G6 -> 0.29300051 | H14: ='Cost Build-up'!H6 -> 0.2848227 | I14: ='Cost Build-up'!I6 -> 0.19449399 | J14: ='Cost Build-up'!J6 -> 0.18420916 | K14: ='Cost Build-up'!K6 -> 0.1777896 | L14: =CHOOSE($L$2,L77,L78,L79) -> 0.19 | M14: =CHOOSE($L$2,M77,M78,M79) -> 0.2 | N14: =CHOOSE($L$2,N77,N78,N79) -> 0.21 | O14: =CHOOSE($L$2,O77,O78,O79) -> 0.22 | P14: =CHOOSE($L$2,P77,P78,P79) -> 0.23
A16: ENERGY GENERATION & STORAGE | AA16: ENERGY GENERATION & STORAGE | Revenue growth — 30% in FY2026E decelerating to 15% by FY2030E ($12,771M → $33,794M). The fastest-growing modelled segment; deceleration reflects a larger base, not weaker demand. Gross margin — 30.0% rising to 32.0% as deployments scale and mix shifts toward grid-scale storage.
C17: Energy Revenue Growth % | H17: ='Revenue Build-up'!H12/'Revenue Build-up'!G12-1 -> 0.40157763 | I17: ='Revenue Build-up'!I12/'Revenue Build-up'!H12-1 -> 0.54387311 | J17: ='Revenue Build-up'!J12/'Revenue Build-up'!I12-1 -> 0.67125104 | K17: ='Revenue Build-up'!K12/'Revenue Build-up'!J12-1 -> 0.26621059 | L17: =CHOOSE($L$2,L80,L81,L82) -> 0.3 | M17: =CHOOSE($L$2,M80,M81,M82) -> 0.25 | N17: =CHOOSE($L$2,N80,N81,N82) -> 0.2 | O17: =CHOOSE($L$2,O80,O81,O82) -> 0.18 | P17: =CHOOSE($L$2,P80,P81,P82) -> 0.15
C18: Energy Gross Margin % | G18: ='Cost Build-up'!G11 -> -0.046253137 | H18: ='Cost Build-up'!H11 -> 0.073676132 | I18: ='Cost Build-up'!I11 -> 0.18906379 | J18: ='Cost Build-up'!J11 -> 0.26174896 | K18: ='Cost Build-up'!K11 -> 0.29770574 | L18: =CHOOSE($L$2,L83,L84,L85) -> 0.3 | M18: =CHOOSE($L$2,M83,M84,M85) -> 0.31 | N18: =CHOOSE($L$2,N83,N84,N85) -> 0.32 | O18: =CHOOSE($L$2,O83,O84,O85) -> 0.32 | P18: =CHOOSE($L$2,P83,P84,P85) -> 0.32
A20: SERVICES & OTHER | AA20: SERVICES & OTHER | Revenue growth — 15% decelerating to 11%, tied to the growing installed vehicle base — after-sales, used vehicles, charging and insurance. Gross margin — 12.0% rising to 15.0% on maturing service economics; kept well below the other segments because the mix stays weighted to lower-margin activity.
C21: Services & Other Revenue Growth % | H21: ='Revenue Build-up'!H15/'Revenue Build-up'!G15-1 -> 0.60205155 | I21: ='Revenue Build-up'!I15/'Revenue Build-up'!H15-1 -> 0.36578559 | J21: ='Revenue Build-up'!J15/'Revenue Build-up'!I15-1 -> 0.26625796 | K21: ='Revenue Build-up'!K15/'Revenue Build-up'!J15-1 -> 0.18948168 | L21: =CHOOSE($L$2,L86,L87,L88) -> 0.15 | M21: =CHOOSE($L$2,M86,M87,M88) -> 0.14 | N21: =CHOOSE($L$2,N86,N87,N88) -> 0.13 | O21: =CHOOSE($L$2,O86,O87,O88) -> 0.12 | P21: =CHOOSE($L$2,P86,P87,P88) -> 0.11
C22: Services Gross Margin % | G22: ='Cost Build-up'!G16 -> -0.027354024 | H22: ='Cost Build-up'!H16 -> 0.034641274 | I22: ='Cost Build-up'!I16 -> 0.058781103 | J22: ='Cost Build-up'!J16 -> 0.058192519 | K22: ='Cost Build-up'!K16 -> 0.074301676 | L22: =CHOOSE($L$2,L89,L90,L91) -> 0.12 | M22: =CHOOSE($L$2,M89,M90,M91) -> 0.13 | N22: =CHOOSE($L$2,N89,N90,N91) -> 0.14 | O22: =CHOOSE($L$2,O89,O90,O91) -> 0.15 | P22: =CHOOSE($L$2,P89,P90,P91) -> 0.15
A24: OPERATING COSTS | AA24: OPERATING EXPENSES | R&D — 7.0% of revenue falling to 6.0%. Absolute spend still rises every year — the ratio falls because revenue grows faster, giving leverage without assuming a cut in investment. SG&A — 6.0% of revenue falling to 5.0% on the same logic. Restructuring is set to nil, being non-recurring.
C25: R&D as % of Total Revenue | G25: ='Cost Build-up'!G24/'Revenue Build-up'!G18 -> 0.04817643 | H25: ='Cost Build-up'!H24/'Revenue Build-up'!H18 -> 0.037747661 | I25: ='Cost Build-up'!I24/'Revenue Build-up'!I18 -> 0.041013506 | J25: ='Cost Build-up'!J24/'Revenue Build-up'!J18 -> 0.046473539 | K25: ='Cost Build-up'!K24/'Revenue Build-up'!K18 -> 0.067607327 | L25: =CHOOSE($L$2,L92,L93,L94) -> 0.07 | M25: =CHOOSE($L$2,M92,M93,M94) -> 0.07 | N25: =CHOOSE($L$2,N92,N93,N94) -> 0.065 | O25: =CHOOSE($L$2,O92,O93,O94) -> 0.06 | P25: =CHOOSE($L$2,P92,P93,P94) -> 0.06
C26: SG&A as % of Total Revenue | G26: ='Cost Build-up'!G26/'Revenue Build-up'!G18 -> 0.08392323 | H26: ='Cost Build-up'!H26/'Revenue Build-up'!H18 -> 0.048439763 | I26: ='Cost Build-up'!I26/'Revenue Build-up'!I18 -> 0.049600612 | J26: ='Cost Build-up'!J26/'Revenue Build-up'!J18 -> 0.052717781 | K26: ='Cost Build-up'!K26/'Revenue Build-up'!K18 -> 0.061522562 | L26: =CHOOSE($L$2,L95,L96,L97) -> 0.06 | M26: =CHOOSE($L$2,M95,M96,M97) -> 0.058 | N26: =CHOOSE($L$2,N95,N96,N97) -> 0.055 | O26: =CHOOSE($L$2,O95,O96,O97) -> 0.053 | P26: =CHOOSE($L$2,P95,P96,P97) -> 0.05
A28: WORKING CAPITAL & BALANCE SHEET DRIVERS | AA28: WORKING CAPITAL | Receivable, inventory and payable days — 18 → 17, 55 → 48 and 62 → 60 respectively: modest efficiency gains consistent with a maturing manufacturing base, not an aggressive release of working capital. Other current assets and accrued liabilities — 38% → 42% and 13% → 12% of revenue, both held close to their historical relationship to the top line. Deferred revenue — held at 3.5% of revenue for the current and non-current portions alike, in line with FY2023–FY2025 actuals. Why ratios, not plugs — each item is driven off revenue or COGS, so the balance sheet and cash flow statement respond consistently whenever the revenue build changes.
C29: Accounts Receivable (Days of Revenue) | G29: =BS!G6/IS!G8*365 -> 12.972986 | H29: =BS!H6/IS!H8*365 -> 13.226781 | I29: =BS!I6/IS!I8*365 -> 13.23117 | J29: =BS!J6/IS!J8*365 -> 16.507012 | K29: =BS!K6/IS!K8*365 -> 17.613549 | L29: 18 | M29: 18 | N29: 17 | O29: 17 | P29: 17
C30: Inventory (Days of COGS) | G30: =BS!G7/IS!G14*365 -> 52.249173 | H30: =BS!H7/IS!H14*365 -> 77.319128 | I30: =BS!I7/IS!I14*365 -> 62.865648 | J30: =BS!J7/IS!J14*365 -> 54.663572 | K30: =BS!K7/IS!K14*365 -> 58.187385 | L30: 55 | M30: 53 | N30: 50 | O30: 48 | P30: 48
C31: Accounts Payable (Days of COGS) | G31: =BS!G17/IS!G14*365 -> 90.984534 | H31: =BS!H17/IS!H14*365 -> 91.868782 | I31: =BS!I17/IS!I14*365 -> 66.579639 | J31: =BS!J17/IS!J14*365 -> 56.742398 | K31: =BS!K17/IS!K14*365 -> 62.784339 | L31: 62 | M31: 62 | N31: 60 | O31: 60 | P31: 60
C32: Other Current Assets (% of Revenue) | G32: =BS!G8/'Revenue Build-up'!G18 -> 0.03444624 | H32: =BS!H8/'Revenue Build-up'!H18 -> 0.10892195 | I32: =BS!I8/'Revenue Build-up'!I18 -> 0.16620338 | J32: =BS!J8/'Revenue Build-up'!J18 -> 0.26395742 | K32: =BS!K8/'Revenue Build-up'!K18 -> 0.37079102 | L32: 0.38 | M32: 0.39 | N32: 0.4 | O32: 0.41 | P32: 0.42
C33: Accrued Liabilities & Other (% of Revenue) | G33: =BS!G18/'Revenue Build-up'!G18 -> 0.12344165 | H33: =BS!H18/'Revenue Build-up'!H18 -> 0.10072181 | I33: =BS!I18/'Revenue Build-up'!I18 -> 0.093827824 | J33: =BS!J18/'Revenue Build-up'!J18 -> 0.10976559 | K33: =BS!K18/'Revenue Build-up'!K18 -> 0.14003396 | L33: 0.13 | M33: 0.13 | N33: 0.125 | O33: 0.125 | P33: 0.12
C34: Deferred Revenue - Current (% of Revenue) | G34: =BS!G19/'Revenue Build-up'!G18 -> 0.026884417 | H34: =BS!H19/'Revenue Build-up'!H18 -> 0.021445582 | I34: =BS!I19/'Revenue Build-up'!I18 -> 0.029595032 | J34: =BS!J19/'Revenue Build-up'!J18 -> 0.032429112 | K34: =BS!K19/'Revenue Build-up'!K18 -> 0.03610786 | L34: 0.035 | M34: 0.035 | N34: 0.035 | O34: 0.035 | P34: 0.035
C35: Operating Lease ROU Assets (% of Revenue) | G35: =BS!G12/'Revenue Build-up'!G18 -> 0.037456106 | H35: =BS!H12/'Revenue Build-up'!H18 -> 0.031462522 | I35: =BS!I12/'Revenue Build-up'!I18 -> 0.043193866 | J35: =BS!J12/'Revenue Build-up'!J18 -> 0.052820145 | K35: =BS!K12/'Revenue Build-up'!K18 -> 0.063557847 | L35: 0.06 | M35: 0.06 | N35: 0.06 | O35: 0.06 | P35: 0.06
C36: Deferred Revenue - Non-Current (% of Revenue) | G36: =BS!G24/'Revenue Build-up'!G18 -> 0.038124965 | H36: =BS!H24/'Revenue Build-up'!H18 -> 0.034420957 | I36: =BS!I24/'Revenue Build-up'!I18 -> 0.033594081 | J36: =BS!J24/'Revenue Build-up'!J18 -> 0.033954345 | K36: =BS!K24/'Revenue Build-up'!K18 -> 0.038290782 | L36: 0.035 | M36: 0.035 | N36: 0.035 | O36: 0.035 | P36: 0.035
C37: Other Non-Current Assets (% of Revenue) | G37: =BS!G13/'Revenue Build-up'!G18 -> 0.26254575 | H37: =BS!H13/'Revenue Build-up'!H18 -> 0.18794039 | I37: =BS!I13/'Revenue Build-up'!I18 -> 0.23867194 | J37: =BS!J13/'Revenue Build-up'!J18 -> 0.232511 | K37: =BS!K13/'Revenue Build-up'!K18 -> 0.23721092 | L37: 0.22 | M37: 0.21 | N37: 0.2 | O37: 0.2 | P37: 0.19
C38: Other Non-Current Liabilities (% of Revenue) | G38: =BS!G25/'Revenue Build-up'!G18 -> 0.076435725 | H38: =BS!H25/'Revenue Build-up'!H18 -> 0.070450026 | I38: =BS!I25/'Revenue Build-up'!I18 -> 0.086749403 | J38: =BS!J25/'Revenue Build-up'!J18 -> 0.10807657 | K38: =BS!K25/'Revenue Build-up'!K18 -> 0.13561538 | L38: 0.13 | M38: 0.125 | N38: 0.12 | O38: 0.12 | P38: 0.115
A40: CAPITAL EXPENDITURE & DEPRECIATION | AA40: CAPEX & DEPRECIATION | CapEx — 10.0% of revenue falling to 8.0% — absolute capital expenditure still rises to $12,913M by FY2030E while the intensity of the current expansion phase moderates. Depreciation — 16.5% of opening net PP&E falling to 15.0%, applied through the asset schedule so PP&E rolls forward on capex less depreciation.
C41: CapEx as % of Total Revenue | G41: ='Asset Schedule'!G6/'Revenue Build-up'!G18 -> 0.12043179 | H41: ='Asset Schedule'!H6/'Revenue Build-up'!H18 -> 0.087869191 | I41: ='Asset Schedule'!I6/'Revenue Build-up'!I18 -> 0.091957467 | J41: ='Asset Schedule'!J6/'Revenue Build-up'!J18 -> 0.11610196 | K41: ='Asset Schedule'!K6/'Revenue Build-up'!K18 -> 0.089921647 | L41: =CHOOSE($L$2,L98,L99,L100) -> 0.1 | M41: =CHOOSE($L$2,M98,M99,M100) -> 0.095 | N41: =CHOOSE($L$2,N98,N99,N100) -> 0.09 | O41: =CHOOSE($L$2,O98,O99,O100) -> 0.085 | P41: =CHOOSE($L$2,P98,P99,P100) -> 0.08
C42: Depreciation Rate (% of Opening Net PP&E) | G42: ='Asset Schedule'!G11 -> 0.22836746 | H42: ='Asset Schedule'!H11 -> 0.19842194 | I42: ='Asset Schedule'!I11 -> 0.19819093 | J42: ='Asset Schedule'!J11 -> 0.18058873 | K42: ='Asset Schedule'!K11 -> 0.17155933 | L42: 0.165 | M42: 0.16 | N42: 0.155 | O42: 0.15 | P42: 0.15
A44: LOANS & OTHER INCOME | AA44: FINANCING, TAX & EQUITY | Debt — held flat at the FY2025A closing balance with no net new borrowing; interest expense at 5.0% on the average balance. Return on cash — 4.5% falling to 4.0%, applied to the prior-year cash balance so the model stays free of circular references. Tax — normalised at 24.0%, replacing the distorted FY2023 actual (a one-off valuation-allowance release). Equity — stock-based compensation and net issuance at 4.0% of revenue falling to 3.5%; no dividends are assumed.
C45: Effective Interest Rate on Debt | G45: ='Loans & Other Income'!G11/'Loans & Other Income'!G5 -> 0.031741958 | H45: ='Loans & Other Income'!H11/'Loans & Other Income'!H5 -> 0.027948493 | I45: ='Loans & Other Income'!I11/'Loans & Other Income'!I5 -> 0.050338819 | J45: ='Loans & Other Income'!J11/'Loans & Other Income'!J5 -> 0.066921606 | K45: ='Loans & Other Income'!K11/'Loans & Other Income'!K5 -> 0.041154268 | L45: 0.05 | M45: 0.05 | N45: 0.05 | O45: 0.05 | P45: 0.05
C46: Return Rate on Cash & Investments | G46: ='Loans & Other Income'!G16/'Loans & Other Income'!G14 -> 0.003030303 | H46: ='Loans & Other Income'!H16/'Loans & Other Income'!H14 -> 0.017558899 | I46: ='Loans & Other Income'!I16/'Loans & Other Income'!I14 -> 0.065296622 | J46: ='Loans & Other Income'!J16/'Loans & Other Income'!J14 -> 0.096444048 | K46: ='Loans & Other Income'!K16/'Loans & Other Income'!K14 -> 0.10290334 | L46: 0.045 | M46: 0.045 | N46: 0.045 | O46: 0.04 | P46: 0.04
A48: TAX
C49: Effective / Normalized Tax Rate | G49: ='Tax Schedule'!G7 -> 0.11020022 | H49: ='Tax Schedule'!H7 -> 0.082513303 | I49: ='Tax Schedule'!I7 -> -0.50145393 | J49: ='Tax Schedule'!J7 -> 0.20433815 | K49: ='Tax Schedule'!K7 -> 0.2696097 | L49: 0.24 | M49: 0.24 | N49: 0.24 | O49: 0.24 | P49: 0.24
...

Sheet Revenue Build-up
A1: TESLA, INC. | E1: ◄ Cover | G1: REVENUE BUILD-UP
A2: USD millions except per-share and operating data
E3: Unit | G3: FY21A | H3: FY22A | I3: FY23A | J3: FY24A | K3: FY25A | L3: FY26E | M3: FY27E | N3: FY28E | O3: FY29E | P3: FY30E
A4: AUTOMOTIVE
C5: Vehicle Deliveries | E5: units | G5: 936172 | H5: 1313851 | I5: 1808581 | J5: 1789226 | K5: 1636129 | L5: =K5*(1+Assumptions!L7) -> 1734296.7 | M5: =L5*(1+Assumptions!M7) -> 1907726.4 | N5: =M5*(1+Assumptions!N7) -> 2136653.6 | O5: =N5*(1+Assumptions!O7) -> 2350318.9 | P5: =O5*(1+Assumptions!P7) -> 2538344.5
C6: Implied Automotive Revenue per Delivery | E6: $/unit | G6: 48887.384 | H6: 53039.5 | I6: 44581.36 | J6: 41530.248 | K6: 41276.085 | L6: =K6*(1+Assumptions!L10) -> 40037.803 | M6: =L6*(1+Assumptions!M10) -> 39237.047 | N6: =M6*(1+Assumptions!N10) -> 39629.417 | O6: =N6*(1+Assumptions!O10) -> 40025.711 | P6: =O6*(1+Assumptions!P10) -> 40826.225
C7: Automotive Sales & Leasing Revenue | E7: $M | G7: =G5*G6/1000000 -> 45767 | H7: =H5*H6/1000000 -> 69686 | I7: =I5*I6/1000000 -> 80629 | J7: =J5*J6/1000000 -> 74307 | K7: =K5*K6/1000000 -> 67533 | L7: =L5*L6/1000000 -> 69437.431 | M7: =M5*M6/1000000 -> 74853.55 | N7: =N5*N6/1000000 -> 84674.336 | ... P7: =P5*P6/1000000 -> 103631.02
C8: [+] Automotive Regulatory Credits | E8: $M | G8: 1465 | H8: 1776 | I8: 1790 | J8: 2763 | K8: 1993 | L8: =K8*(1+Assumptions!L12) -> 1395.1 | M8: =L8*(1+Assumptions!M12) -> 1116.08 | N8: =M8*(1+Assumptions!N12) -> 1004.472 | O8: =N8*(1+Assumptions!O12) -> 954.2484 | P8: =O8*(1+Assumptions!P12) -> 906.53598
C9: Total Automotive Revenue | G9: =SUM(G7:G8) -> 47232 | H9: =SUM(H7:H8) -> 71462 | I9: =SUM(I7:I8) -> 82419 | J9: =SUM(J7:J8) -> 77070 | K9: =SUM(K7:K8) -> 69526 | L9: =SUM(L7:L8) -> 70832.531 | M9: =SUM(M7:M8) -> 75969.63 | N9: =SUM(N7:N8) -> 85678.808 | ... P9: =SUM(P7:P8) -> 104537.56
A11: ENERGY GENERATION & STORAGE
C12: Energy Generation & Storage Revenue | E12: $M | G12: 2789 | H12: 3909 | I12: 6035 | J12: 10086 | K12: 12771 | L12: =K12*(1+Assumptions!L17) -> 16602.3 | M12: =L12*(1+Assumptions!M17) -> 20752.875 | N12: =M12*(1+Assumptions!N17) -> 24903.45 | O12: =N12*(1+Assumptions!O17) -> 29386.071 | P12: =O12*(1+Assumptions!P17) -> 33793.982
A14: SERVICES & OTHER
C15: Services & Other Revenue | E15: $M | G15: 3802 | H15: 6091 | I15: 8319 | J15: 10534 | K15: 12530 | L15: =K15*(1+Assumptions!L21) -> 14409.5 | M15: =L15*(1+Assumptions!M21) -> 16426.83 | N15: =M15*(1+Assumptions!N21) -> 18562.318 | O15: =N15*(1+Assumptions!O21) -> 20789.796 | P15: =O15*(1+Assumptions!P21) -> 23076.674
A17: TOTAL REVENUE
C18: TOTAL REVENUE | E18: $M | G18: =G9+G12+G15 -> 53823 | H18: =H9+H12+H15 -> 81462 | I18: =I9+I12+I15 -> 96773 | J18: =J9+J12+J15 -> 97690 | K18: =K9+K12+K15 -> 94827 | L18: =L9+L12+L15 -> 101844.33 | M18: =M9+M12+M15 -> 113149.34 | N18: =N9+N12+N15 -> 129144.58 | ... P18: =P9+P12+P15 -> 161408.21
C19: YoY Growth % | H19: =H18/G18-1 -> 0.51351653 | I19: =I18/H18-1 -> 0.18795267 | J19: =J18/I18-1 -> 0.0094757835 | K19: =K18/J18-1 -> -0.029306992 | L19: =L18/K18-1 -> 0.074001398 | M19: =M18/L18-1 -> 0.11100279 | N19: =N18/M18-1 -> 0.14136398 | O19: =O18/N18-1 -> 0.12434689 | P19: =P18/O18-1 -> 0.11160154
A21: ENERGY OPERATING CROSS-CHECK — STORAGE DEPLOYMENTS (CONTEXT, NOT A FORECAST DRIVER)
C22: Energy Storage Deployed | E22: GWh | G22: 3.99 | H22: 6.5 | I22: 14.7 | J22: 31.4 | K22: 46.7
C23: Implied Energy Revenue per GWh Deployed | E23: $M/GWh | G23: =G12/G22 -> 698.99749 | H23: =H12/H22 -> 601.38462 | I23: =I12/I22 -> 410.54422 | J23: =J12/J22 -> 321.21019 | K23: =K12/K22 -> 273.46895
C24: Implied Deployments at Forecast Revenue — $/GWh held flat | E24: GWh | L24: =L12/$K$23 -> 60.71 | M24: =M12/$K$23 -> 75.8875 | N24: =N12/$K$23 -> 91.065 | O24: =O12/$K$23 -> 107.4567 | P24: =P12/$K$23 -> 123.5752
C25: Implied Deployments at Forecast Revenue — $/GWh falling 10% p.a. | E25: GWh | L25: =L12/($K$23*0.9^1) -> 67.455556 | M25: =M12/($K$23*0.9^2) -> 93.688272 | N25: =N12/($K$23*0.9^3) -> 124.9177 | O25: =O12/($K$23*0.9^4) -> 163.78098 | P25: =P12/($K$23*0.9^5) -> 209.27569
A26: Deployments are Tesla's disclosed annual energy-storage figures (FY2021A–FY2025A). Revenue per GWh is a blended segment metric — the Energy segment also contains solar — and it has fallen every year, so it is used here as a plausibility cross-check on the revenue forecast, not as a forecast driver. Rows 24–25 show the deployment volumes the Base Case revenue implies under two $/GWh paths; both are a multiple of FY2025A, which is the growth the Energy assumption embeds. Tesla does not disclose a stable storage-only price or mix, so no revenue-per-GWh forecast is built. Sources: see Sources & Notes.

Sheet Cost Build-up
A1: TESLA, INC. | E1: ◄ Cover | G1: COST BUILD-UP
A2: USD millions except per-share and operating data
E3: Unit | G3: FY21A | H3: FY22A | I3: FY23A | J3: FY24A | K3: FY25A | L3: FY26E | M3: FY27E | N3: FY28E | O3: FY29E | P3: FY30E
A4: AUTOMOTIVE
C5: Automotive Revenue | E5: $M | G5: ='Revenue Build-up'!G9 -> 47232 | H5: ='Revenue Build-up'!H9 -> 71462 | I5: ='Revenue Build-up'!I9 -> 82419 | J5: ='Revenue Build-up'!J9 -> 77070 | K5: ='Revenue Build-up'!K9 -> 69526 | L5: ='Revenue Build-up'!L9 -> 70832.531 | M5: ='Revenue Build-up'!M9 -> 75969.63 | N5: ='Revenue Build-up'!N9 -> 85678.808 | ... P5: ='Revenue Build-up'!P9 -> 104537.56
C6: Automotive Gross Margin % | G6: =1-G7/G5 -> 0.29300051 | H6: =1-H7/H5 -> 0.2848227 | I6: =1-I7/I5 -> 0.19449399 | J6: =1-J7/J5 -> 0.18420916 | K6: =1-K7/K5 -> 0.1777896 | L6: =Assumptions!L14 -> 0.19 | M6: =Assumptions!M14 -> 0.2 | N6: =Assumptions!N14 -> 0.21 | O6: =Assumptions!O14 -> 0.22 | P6: =Assumptions!P14 -> 0.23
C7: Automotive Cost of Revenue | E7: $M | G7: 33393 | H7: 51108 | I7: 66389 | J7: 62873 | K7: 57165 | L7: =L5*(1-L6) -> 57374.35 | M7: =M5*(1-M6) -> 60775.704 | N7: =N5*(1-N6) -> 67686.258 | O7: =O5*(1-O6) -> 74121.4 | P7: =P5*(1-P6) -> 80493.92
A9: ENERGY GENERATION & STORAGE
C10: Energy Revenue | E10: $M | G10: ='Revenue Build-up'!G12 -> 2789 | H10: ='Revenue Build-up'!H12 -> 3909 | I10: ='Revenue Build-up'!I12 -> 6035 | J10: ='Revenue Build-up'!J12 -> 10086 | K10: ='Revenue Build-up'!K12 -> 12771 | L10: ='Revenue Build-up'!L12 -> 16602.3 | M10: ='Revenue Build-up'!M12 -> 20752.875 | N10: ='Revenue Build-up'!N12 -> 24903.45 | ... P10: ='Revenue Build-up'!P12 -> 33793.982
C11: Energy Gross Margin % | G11: =1-G12/G10 -> -0.046253137 | H11: =1-H12/H10 -> 0.073676132 | I11: =1-I12/I10 -> 0.18906379 | J11: =1-J12/J10 -> 0.26174896 | K11: =1-K12/K10 -> 0.29770574 | L11: =Assumptions!L18 -> 0.3 | M11: =Assumptions!M18 -> 0.31 | N11: =Assumptions!N18 -> 0.32 | O11: =Assumptions!O18 -> 0.32 | P11: =Assumptions!P18 -> 0.32
C12: Energy Cost of Revenue | E12: $M | G12: 2918 | H12: 3621 | I12: 4894 | J12: 7446 | K12: 8969 | L12: =L10*(1-L11) -> 11621.61 | M12: =M10*(1-M11) -> 14319.484 | N12: =N10*(1-N11) -> 16934.346 | O12: =O10*(1-O11) -> 19982.528 | P12: =P10*(1-P11) -> 22979.908
A14: SERVICES & OTHER
C15: Services & Other Revenue | E15: $M | G15: ='Revenue Build-up'!G15 -> 3802 | H15: ='Revenue Build-up'!H15 -> 6091 | I15: ='Revenue Build-up'!I15 -> 8319 | J15: ='Revenue Build-up'!J15 -> 10534 | K15: ='Revenue Build-up'!K15 -> 12530 | L15: ='Revenue Build-up'!L15 -> 14409.5 | M15: ='Revenue Build-up'!M15 -> 16426.83 | N15: ='Revenue Build-up'!N15 -> 18562.318 | ... P15: ='Revenue Build-up'!P15 -> 23076.674
C16: Services Gross Margin % | G16: =1-G17/G15 -> -0.027354024 | H16: =1-H17/H15 -> 0.034641274 | I16: =1-I17/I15 -> 0.058781103 | J16: =1-J17/J15 -> 0.058192519 | K16: =1-K17/K15 -> 0.074301676 | L16: =Assumptions!L22 -> 0.12 | M16: =Assumptions!M22 -> 0.13 | N16: =Assumptions!N22 -> 0.14 | O16: =Assumptions!O22 -> 0.15 | P16: =Assumptions!P22 -> 0.15
C17: Services Cost of Revenue | E17: $M | G17: 3906 | H17: 5880 | I17: 7830 | J17: 9921 | K17: 11599 | L17: =L15*(1-L16) -> 12680.36 | M17: =M15*(1-M16) -> 14291.342 | N17: =N15*(1-N16) -> 15963.593 | O17: =O15*(1-O16) -> 17671.327 | P17: =P15*(1-P16) -> 19615.173
A19: TOTAL COST OF REVENUE
C20: TOTAL COST OF REVENUE | E20: $M | G20: =G7+G12+G17 -> 40217 | H20: =H7+H12+H17 -> 60609 | I20: =I7+I12+I17 -> 79113 | J20: =J7+J12+J17 -> 80240 | K20: =K7+K12+K17 -> 77733 | L20: =L7+L12+L17 -> 81676.32 | M20: =M7+M12+M17 -> 89386.53 | N20: =N7+N12+N17 -> 100584.2 | ... P20: =P7+P12+P17 -> 123089
A22: OPERATING EXPENSES
C23: R&D as % of Total Revenue | G23: =Assumptions!G25 -> 0.04817643 | H23: =Assumptions!H25 -> 0.037747661 | I23: =Assumptions!I25 -> 0.041013506 | J23: =Assumptions!J25 -> 0.046473539 | K23: =Assumptions!K25 -> 0.067607327 | L23: =Assumptions!L25 -> 0.07 | M23: =Assumptions!M25 -> 0.07 | N23: =Assumptions!N25 -> 0.065 | ... P23: =Assumptions!P25 -> 0.06
C24: Research & Development | E24: $M | G24: 2593 | H24: 3075 | I24: 3969 | J24: 4540 | K24: 6411 | L24: ='Revenue Build-up'!L18*L23 -> 7129.1031 | M24: ='Revenue Build-up'!M18*M23 -> 7920.4535 | N24: ='Revenue Build-up'!N18*N23 -> 8394.3974 | O24: ='Revenue Build-up'!O18*O23 -> 8712.1982 | P24: ='Revenue Build-up'!P18*P23 -> 9684.4929
C25: SG&A as % of Total Revenue | G25: =Assumptions!G26 -> 0.08392323 | H25: =Assumptions!H26 -> 0.048439763 | I25: =Assumptions!I26 -> 0.049600612 | J25: =Assumptions!J26 -> 0.052717781 | K25: =Assumptions!K26 -> 0.061522562 | L25: =Assumptions!L26 -> 0.06 | M25: =Assumptions!M26 -> 0.058 | N25: =Assumptions!N26 -> 0.055 | ... P25: =Assumptions!P26 -> 0.05
C26: Selling, General & Administrative | E26: $M | G26: 4517 | H26: 3946 | I26: 4800 | J26: 5150 | K26: 5834 | L26: ='Revenue Build-up'!L18*L25 -> 6110.6598 | M26: ='Revenue Build-up'!M18*M25 -> 6562.6614 | N26: ='Revenue Build-up'!N18*N25 -> 7102.9517 | O26: ='Revenue Build-up'!O18*O25 -> 7695.775 | P26: ='Revenue Build-up'!P18*P25 -> 8070.4107
C27: Restructuring & Other | E27: $M | G27: -27 | H27: 176 | I27: 0 | J27: 684 | K27: 494 | L27: 0 | M27: 0 | N27: 0 | O27: 0 | P27: 0
C29: Total Operating Expenses | E29: $M | G29: =SUM(G24,G26,G27) -> 7083 | H29: =SUM(H24,H26,H27) -> 7197 | I29: =SUM(I24,I26,I27) -> 8769 | J29: =SUM(J24,J26,J27) -> 10374 | K29: =SUM(K24,K26,K27) -> 12739 | L29: =SUM(L24,L26,L27) -> 13239.763 | M29: =SUM(M24,M26,M27) -> 14483.115 | N29: =SUM(N24,N26,N27) -> 15497.349 | ... P29: =SUM(P24,P26,P27) -> 17754.904

Sheet IS
A1: TESLA, INC. | E1: ◄ Cover | G1: INCOME STATEMENT
A2: USD millions except per-share and operating data
E3: Unit | G3: FY21A | H3: FY22A | I3: FY23A | J3: FY24A | K3: FY25A | L3: FY26E | M3: FY27E | N3: FY28E | O3: FY29E | P3: FY30E
A4: REVENUE
C5: Automotive Revenue | E5: $M | G5: ='Revenue Build-up'!G9 -> 47232 | H5: ='Revenue Build-up'!H9 -> 71462 | I5: ='Revenue Build-up'!I9 -> 82419 | J5: ='Revenue Build-up'!J9 -> 77070 | K5: ='Revenue Build-up'!K9 -> 69526 | L5: ='Revenue Build-up'!L9 -> 70832.531 | M5: ='Revenue Build-up'!M9 -> 75969.63 | N5: ='Revenue Build-up'!N9 -> 85678.808 | ... P5: ='Revenue Build-up'!P9 -> 104537.56
C6: Energy Generation & Storage Revenue | E6: $M | G6: ='Revenue Build-up'!G12 -> 2789 | H6: ='Revenue Build-up'!H12 -> 3909 | I6: ='Revenue Build-up'!I12 -> 6035 | J6: ='Revenue Build-up'!J12 -> 10086 | K6: ='Revenue Build-up'!K12 -> 12771 | L6: ='Revenue Build-up'!L12 -> 16602.3 | M6: ='Revenue Build-up'!M12 -> 20752.875 | N6: ='Revenue Build-up'!N12 -> 24903.45 | ... P6: ='Revenue Build-up'!P12 -> 33793.982
C7: Services & Other Revenue | E7: $M | G7: ='Revenue Build-up'!G15 -> 3802 | H7: ='Revenue Build-up'!H15 -> 6091 | I7: ='Revenue Build-up'!I15 -> 8319 | J7: ='Revenue Build-up'!J15 -> 10534 | K7: ='Revenue Build-up'!K15 -> 12530 | L7: ='Revenue Build-up'!L15 -> 14409.5 | M7: ='Revenue Build-up'!M15 -> 16426.83 | N7: ='Revenue Build-up'!N15 -> 18562.318 | ... P7: ='Revenue Build-up'!P15 -> 23076.674
C8: TOTAL REVENUE | E8: $M | G8: =SUM(G5:G7) -> 53823 | H8: =SUM(H5:H7) -> 81462 | I8: =SUM(I5:I7) -> 96773 | J8: =SUM(J5:J7) -> 97690 | K8: =SUM(K5:K7) -> 94827 | L8: =SUM(L5:L7) -> 101844.33 | M8: =SUM(M5:M7) -> 113149.34 | N8: =SUM(N5:N7) -> 129144.58 | ... P8: =SUM(P5:P7) -> 161408.21
A10: COST OF REVENUE
C11: Automotive Cost of Revenue | E11: $M | G11: ='Cost Build-up'!G7 -> 33393 | H11: ='Cost Build-up'!H7 -> 51108 | I11: ='Cost Build-up'!I7 -> 66389 | J11: ='Cost Build-up'!J7 -> 62873 | K11: ='Cost Build-up'!K7 -> 57165 | L11: ='Cost Build-up'!L7 -> 57374.35 | M11: ='Cost Build-up'!M7 -> 60775.704 | N11: ='Cost Build-up'!N7 -> 67686.258 | ... P11: ='Cost Build-up'!P7 -> 80493.92
C12: Energy Cost of Revenue | E12: $M | G12: ='Cost Build-up'!G12 -> 2918 | H12: ='Cost Build-up'!H12 -> 3621 | I12: ='Cost Build-up'!I12 -> 4894 | J12: ='Cost Build-up'!J12 -> 7446 | K12: ='Cost Build-up'!K12 -> 8969 | L12: ='Cost Build-up'!L12 -> 11621.61 | M12: ='Cost Build-up'!M12 -> 14319.484 | N12: ='Cost Build-up'!N12 -> 16934.346 | ... P12: ='Cost Build-up'!P12 -> 22979.908
C13: Services Cost of Revenue | E13: $M | G13: ='Cost Build-up'!G17 -> 3906 | H13: ='Cost Build-up'!H17 -> 5880 | I13: ='Cost Build-up'!I17 -> 7830 | J13: ='Cost Build-up'!J17 -> 9921 | K13: ='Cost Build-up'!K17 -> 11599 | L13: ='Cost Build-up'!L17 -> 12680.36 | M13: ='Cost Build-up'!M17 -> 14291.342 | N13: ='Cost Build-up'!N17 -> 15963.593 | ... P13: ='Cost Build-up'!P17 -> 19615.173
C14: Total Cost of Revenue | E14: $M | G14: =SUM(G11:G13) -> 40217 | H14: =SUM(H11:H13) -> 60609 | I14: =SUM(I11:I13) -> 79113 | J14: =SUM(J11:J13) -> 80240 | K14: =SUM(K11:K13) -> 77733 | L14: =SUM(L11:L13) -> 81676.32 | M14: =SUM(M11:M13) -> 89386.53 | N14: =SUM(N11:N13) -> 100584.2 | ... P14: =SUM(P11:P13) -> 123089
C16: GROSS PROFIT | E16: $M | G16: =G8-G14 -> 13606 | H16: =H8-H14 -> 20853 | I16: =I8-I14 -> 17660 | J16: =J8-J14 -> 17450 | K16: =K8-K14 -> 17094 | L16: =L8-L14 -> 20168.011 | M16: =M8-M14 -> 23762.805 | N16: =N8-N14 -> 28560.378 | ... P16: =P8-P14 -> 38319.214
C17: Gross Margin % | G17: =G16/G8 -> 0.25279156 | H17: =H16/H8 -> 0.25598439 | I17: =I16/I8 -> 0.18248892 | J17: =J16/J8 -> 0.17862627 | K17: =K16/K8 -> 0.18026511 | L17: =L16/L8 -> 0.19802782 | M17: =M16/M8 -> 0.21001277 | N17: =N16/N8 -> 0.22115043 | ... P17: =P16/P8 -> 0.2374056
A19: OPERATING EXPENSES
C20: Research & Development | E20: $M | G20: ='Cost Build-up'!G24 -> 2593 | H20: ='Cost Build-up'!H24 -> 3075 | I20: ='Cost Build-up'!I24 -> 3969 | J20: ='Cost Build-up'!J24 -> 4540 | K20: ='Cost Build-up'!K24 -> 6411 | L20: ='Cost Build-up'!L24 -> 7129.1031 | M20: ='Cost Build-up'!M24 -> 7920.4535 | N20: ='Cost Build-up'!N24 -> 8394.3974 | ... P20: ='Cost Build-up'!P24 -> 9684.4929
C21: Selling, General & Administrative | E21: $M | G21: ='Cost Build-up'!G26 -> 4517 | H21: ='Cost Build-up'!H26 -> 3946 | I21: ='Cost Build-up'!I26 -> 4800 | J21: ='Cost Build-up'!J26 -> 5150 | K21: ='Cost Build-up'!K26 -> 5834 | L21: ='Cost Build-up'!L26 -> 6110.6598 | M21: ='Cost Build-up'!M26 -> 6562.6614 | N21: ='Cost Build-up'!N26 -> 7102.9517 | ... P21: ='Cost Build-up'!P26 -> 8070.4107
C22: Restructuring & Other | E22: $M | G22: ='Cost Build-up'!G27 -> -27 | H22: ='Cost Build-up'!H27 -> 176 | I22: ='Cost Build-up'!I27 -> 0 | J22: ='Cost Build-up'!J27 -> 684 | K22: ='Cost Build-up'!K27 -> 494 | L22: ='Cost Build-up'!L27 -> 0 | M22: ='Cost Build-up'!M27 -> 0 | N22: ='Cost Build-up'!N27 -> 0 | ... P22: ='Cost Build-up'!P27 -> 0
C23: Total Operating Expenses | E23: $M | G23: =SUM(G20:G22) -> 7083 | H23: =SUM(H20:H22) -> 7197 | I23: =SUM(I20:I22) -> 8769 | J23: =SUM(J20:J22) -> 10374 | K23: =SUM(K20:K22) -> 12739 | L23: =SUM(L20:L22) -> 13239.763 | M23: =SUM(M20:M22) -> 14483.115 | N23: =SUM(N20:N22) -> 15497.349 | ... P23: =SUM(P20:P22) -> 17754.904
C25: EBIT (Operating Income) | E25: $M | G25: =G16-G23 -> 6523 | H25: =H16-H23 -> 13656 | I25: =I16-I23 -> 8891 | J25: =J16-J23 -> 7076 | K25: =K16-K23 -> 4355 | L25: =L16-L23 -> 6928.2478 | M25: =M16-M23 -> 9279.6903 | N25: =N16-N23 -> 13063.029 | ... P25: =P16-P23 -> 20564.31
C26: EBIT Margin % | G26: =G25/G8 -> 0.12119354 | H26: =H25/H8 -> 0.16763644 | I26: =I25/I8 -> 0.0918748 | J26: =J25/J8 -> 0.072433207 | K26: =K25/K8 -> 0.045925738 | L26: =L25/L8 -> 0.06802782 | M26: =M25/M8 -> 0.082012769 | N26: =N25/N8 -> 0.10115043 | ... P26: =P25/P8 -> 0.1274056
C28: [+] Depreciation & Amortization | E28: $M | G28: ='Asset Schedule'!G7 -> 2911 | H28: ='Asset Schedule'!H7 -> 3747 | I28: ='Asset Schedule'!I7 -> 4667 | J28: ='Asset Schedule'!J7 -> 5368 | K28: ='Asset Schedule'!K7 -> 6148 | L28: ='Asset Schedule'!L7 -> 6706.095 | M28: ='Asset Schedule'!M7 -> 7059.4141 | N28: ='Asset Schedule'!N7 -> 7410.7222 | ... P28: ='Asset Schedule'!P7 -> 8484.3257
C29: EBITDA | E29: $M | G29: =G25+G28 -> 9434 | H29: =H25+H28 -> 17403 | I29: =I25+I28 -> 13558 | J29: =J25+J28 -> 12444 | K29: =K25+K28 -> 10503 | L29: =L25+L28 -> 13634.343 | M29: =M25+M28 -> 16339.104 | N29: =N25+N28 -> 20473.751 | ... P29: =P25+P28 -> 29048.636
C30: EBITDA Margin % | G30: =G29/G8 -> 0.17527823 | H30: =H29/H8 -> 0.21363335 | I30: =I29/I8 -> 0.14010106 | J30: =J29/J8 -> 0.12738254 | K30: =K29/K8 -> 0.11075959 | L30: =L29/L8 -> 0.13387434 | M30: =M29/M8 -> 0.14440301 | N30: =N29/N8 -> 0.15853357 | ... P30: =P29/P8 -> 0.17997
A32: NON-OPERATING ITEMS
C33: [+] Interest Income | E33: $M | G33: ='Loans & Other Income'!G16 -> 56 | H33: ='Loans & Other Income'!H16 -> 297 | I33: ='Loans & Other Income'!I16 -> 1066 | J33: ='Loans & Other Income'!J16 -> 1569 | K33: ='Loans & Other Income'!K16 -> 1680 | L33: ='Loans & Other Income'!L16 -> 743.085 | M33: ='Loans & Other Income'!M16 -> 883.82997 | N33: ='Loans & Other Income'!N16 -> 1064.9972 | ... P33: ='Loans & Other Income'!P16 -> 1435.2462
C34: [-] Interest Expense | E34: $M | G34: ='Loans & Other Income'!G11 -> 371 | H34: ='Loans & Other Income'!H11 -> 191 | I34: ='Loans & Other Income'!I11 -> 156 | J34: ='Loans & Other Income'!J11 -> 350 | K34: ='Loans & Other Income'!K11 -> 338 | L34: ='Loans & Other Income'!L11 -> 418.8 | M34: ='Loans & Other Income'!M11 -> 418.8 | N34: ='Loans & Other Income'!N11 -> 418.8 | ... P34: ='Loans & Other Income'!P11 -> 418.8
C35: [+/-] Other Income (Expense), net | E35: $M | G35: 135 | H35: -43 | I35: 172 | J35: 695 | K35: -419 | L35: 0 | M35: 0 | N35: 0 | O35: 0 | P35: 0
C37: PBT (Income Before Taxes) | E37: $M | G37: =G25+G33-G34+G35 -> 6343 | H37: =H25+H33-H34+H35 -> 13719 | I37: =I25+I33-I34+I35 -> 9973 | J37: =J25+J33-J34+J35 -> 8990 | K37: =K25+K33-K34+K35 -> 5278 | L37: =L25+L33-L34+L35 -> 7252.5328 | M37: =M25+M33-M34+M35 -> 9744.7203 | N37: =N25+N33-N34+N35 -> 13709.226 | ... P37: =P25+P33-P34+P35 -> 21580.756
C38: PBT Margin % | G38: =G37/G8 -> 0.11784925 | H38: =H37/H8 -> 0.16840981 | I38: =I37/I8 -> 0.1030556 | J38: =J37/J8 -> 0.092025796 | K38: =K37/K8 -> 0.055659253 | L38: =L37/L8 -> 0.071211945 | M38: =M37/M8 -> 0.086122647 | N38: =N37/N8 -> 0.1061541 | ... P38: =P37/P8 -> 0.13370296
C40: [-] Income Tax Expense | E40: $M | G40: ='Tax Schedule'!G6 -> 699 | H40: ='Tax Schedule'!H6 -> 1132 | I40: ='Tax Schedule'!I6 -> -5001 | J40: ='Tax Schedule'!J6 -> 1837 | K40: ='Tax Schedule'!K6 -> 1423 | L40: ='Tax Schedule'!L6 -> 1740.6079 | M40: ='Tax Schedule'!M6 -> 2338.7329 | N40: ='Tax Schedule'!N6 -> 3290.2143 | ... P40: ='Tax Schedule'!P6 -> 5179.3815
C41: Effective Tax Rate % | G41: =G40/G37 -> 0.11020022 | H41: =H40/H37 -> 0.082513303 | I41: =I40/I37 -> -0.50145393 | J41: =J40/J37 -> 0.20433815 | K41: =K40/K37 -> 0.2696097 | L41: =L40/L37 -> 0.24 | M41: =M40/M37 -> 0.24 | N41: =N40/N37 -> 0.24 | ... P41: =P40/P37 -> 0.24
C43: NET INCOME | E43: $M | G43: =G37-G40 -> 5644 | H43: =H37-H40 -> 12587 | I43: =I37-I40 -> 14974 | J43: =J37-J40 -> 7153 | K43: =K37-K40 -> 3855 | L43: =L37-L40 -> 5511.925 | M43: =M37-M40 -> 7405.9874 | N43: =N37-N40 -> 10419.012 | ... P43: =P37-P40 -> 16401.375
C44: Net Margin % | G44: =G43/G8 -> 0.10486223 | H44: =H43/H8 -> 0.15451376 | I44: =I43/I8 -> 0.15473324 | J44: =J43/J8 -> 0.073221415 | K44: =K43/K8 -> 0.040652979 | L44: =L43/L8 -> 0.054121078 | M44: =M43/M8 -> 0.065453212 | N44: =N43/N8 -> 0.080677116 | ... P44: =P43/P8 -> 0.10161425
C45: [-] Net Income Attributable to Noncontrolling Interests | G45: 125 | H45: 31 | I45: -23 | J45: 62 | K45: 61 | L45: 0 | M45: 0 | N45: 0 | O45: 0 | P45: 0
C46: NET INCOME ATTRIBUTABLE TO COMMON STOCKHOLDERS | G46: =G43-G45 -> 5519 | H46: =H43-H45 -> 12556 | I46: =I43-I45 -> 14997 | J46: =J43-J45 -> 7091 | K46: =K43-K45 -> 3794 | L46: =L43-L45 -> 5511.925 | M46: =M43-M45 -> 7405.9874 | N46: =N43-N45 -> 10419.012 | ... P46: =P43-P45 -> 16401.375
C47: Diluted Weighted-Average Shares Outstanding | E47: millions | G47: ='Equity Schedule'!G12 -> 3386 | H47: ='Equity Schedule'!H12 -> 3475 | I47: ='Equity Schedule'!I12 -> 3485 | J47: ='Equity Schedule'!J12 -> 3498 | K47: ='Equity Schedule'!K12 -> 3528 | L47: ='Equity Schedule'!L12 -> 3950 | M47: ='Equity Schedule'!M12 -> 3950 | N47: ='Equity Schedule'!N12 -> 3950 | ... P47: ='Equity Schedule'!P12 -> 3950
C48: Diluted EPS | E48: $/share | G48: =G46/G47 -> 1.6299468 | H48: =H46/H47 -> 3.6132374 | I48: =I46/I47 -> 4.3032999 | J48: =J46/J47 -> 2.0271584 | K48: =K46/K47 -> 1.0753968 | L48: =L46/L47 -> 1.395424 | M48: =M46/M47 -> 1.8749335 | N48: =N46/N47 -> 2.6377246 | ... P48: =P46/P47 -> 4.1522468

Sheet BS
A1: TESLA, INC. | E1: ◄ Cover | G1: BALANCE SHEET
A2: USD millions except per-share and operating data
E3: Unit | G3: FY21A | H3: FY22A | I3: FY23A | J3: FY24A | K3: FY25A | L3: FY26E | M3: FY27E | N3: FY28E | O3: FY29E | P3: FY30E
A4: ASSETS
C5: Cash and Cash Equivalents | E5: $M | G5: 17576 | H5: 16253 | I5: 16398 | J5: 16139 | K5: 16513 | L5: =Cashflow!L32 -> 19640.666 | M5: =Cashflow!M32 -> 23666.605 | N5: =Cashflow!N32 -> 28247.664 | O5: =Cashflow!O32 -> 35881.154 | P5: =Cashflow!P32 -> 45753.868
C6: [+] Accounts Receivable | E6: $M | G6: 1913 | H6: 2952 | I6: 3508 | J6: 4418 | K6: 4576 | L6: =IS!L8/365*Assumptions!L29 -> 5022.4601 | M6: =IS!M8/365*Assumptions!M29 -> 5579.9672 | N6: =IS!N8/365*Assumptions!N29 -> 6014.9528 | O6: =IS!O8/365*Assumptions!O29 -> 6762.8936 | P6: =IS!P8/365*Assumptions!P29 -> 7517.6429
C7: [+] Inventory | E7: $M | G7: 5757 | H7: 12839 | I7: 13626 | J7: 12017 | K7: 12392 | L7: =IS!L14/365*Assumptions!L30 -> 12307.391 | M7: =IS!M14/365*Assumptions!M30 -> 12979.414 | N7: =IS!N14/365*Assumptions!N30 -> 13778.657 | O7: =IS!O14/365*Assumptions!O30 -> 14699.212 | P7: =IS!P14/365*Assumptions!P30 -> 16187.047
C8: Short-Term Investments & Other Current Assets | E8: $M | G8: 1854 | H8: 8873 | I8: 16084 | J8: 25786 | K8: 35161 | L8: ='Revenue Build-up'!L18*Assumptions!L32 -> 38700.846 | M8: ='Revenue Build-up'!M18*Assumptions!M32 -> 44128.241 | N8: ='Revenue Build-up'!N18*Assumptions!N32 -> 51657.83 | O8: ='Revenue Build-up'!O18*Assumptions!O32 -> 59533.354 | P8: ='Revenue Build-up'!P18*Assumptions!P32 -> 67791.45
C9: Total Current Assets | E9: $M | G9: =SUM(G5:G8) -> 27100 | H9: =SUM(H5:H8) -> 40917 | I9: =SUM(I5:I8) -> 49616 | J9: =SUM(J5:J8) -> 58360 | K9: =SUM(K5:K8) -> 68642 | L9: =SUM(L5:L8) -> 75671.362 | M9: =SUM(M5:M8) -> 86354.227 | N9: =SUM(N5:N8) -> 99699.105 | ... P9: =SUM(P5:P8) -> 137250.01
C11: Net PP&E | E11: $M | G11: ='Asset Schedule'!G9 -> 18884 | H11: ='Asset Schedule'!H9 -> 23548 | I11: ='Asset Schedule'!I9 -> 29725 | J11: ='Asset Schedule'!J9 -> 35836 | K11: ='Asset Schedule'!K9 -> 40643 | L11: ='Asset Schedule'!L9 -> 44121.338 | M11: ='Asset Schedule'!M9 -> 47811.111 | N11: ='Asset Schedule'!N9 -> 52023.4 | ... P11: ='Asset Schedule'!P9 -> 60990.503
C12: [+] Operating Lease ROU Assets | E12: $M | G12: 2016 | H12: 2563 | I12: 4180 | J12: 5160 | K12: 6027 | L12: ='Revenue Build-up'!L18*Assumptions!L35 -> 6110.6598 | M12: ='Revenue Build-up'!M18*Assumptions!M35 -> 6788.9601 | N12: ='Revenue Build-up'!N18*Assumptions!N35 -> 7748.6746 | O12: ='Revenue Build-up'!O18*Assumptions!O35 -> 8712.1982 | P12: ='Revenue Build-up'!P18*Assumptions!P35 -> 9684.4929
C13: [+] Other Non-Current Assets | E13: $M | G13: 14131 | H13: 15310 | I13: 23097 | J13: 22714 | K13: 22494 | L13: ='Revenue Build-up'!L18*Assumptions!L37 -> 22405.753 | M13: ='Revenue Build-up'!M18*Assumptions!M37 -> 23761.36 | N13: ='Revenue Build-up'!N18*Assumptions!N37 -> 25828.915 | O13: ='Revenue Build-up'!O18*Assumptions!O37 -> 29040.661 | P13: ='Revenue Build-up'!P18*Assumptions!P37 -> 30667.561
C14: TOTAL ASSETS | E14: $M | G14: =G9+SUM(G11:G13) -> 62131 | H14: =H9+SUM(H11:H13) -> 82338 | I14: =I9+SUM(I11:I13) -> 106618 | J14: =J9+SUM(J11:J13) -> 122070 | K14: =K9+SUM(K11:K13) -> 137806 | L14: =L9+SUM(L11:L13) -> 148309.11 | M14: =M9+SUM(M11:M13) -> 164715.66 | N14: =N9+SUM(N11:N13) -> 185300.09 | ... P14: =P9+SUM(P11:P13) -> 238592.56
A16: LIABILITIES
C17: Accounts Payable | E17: $M | G17: 10025 | H17: 15255 | I17: 14431 | J17: 12474 | K17: 13371 | L17: =IS!L14/365*Assumptions!L31 -> 13873.786 | M17: =IS!M14/365*Assumptions!M31 -> 15183.465 | N17: =IS!N14/365*Assumptions!N31 -> 16534.389 | O17: =IS!O14/365*Assumptions!O31 -> 18374.014 | P17: =IS!P14/365*Assumptions!P31 -> 20233.808
C18: [+] Accrued Liabilities & Other | E18: $M | G18: 6644 | H18: 8205 | I18: 9080 | J18: 10723 | K18: 13279 | L18: ='Revenue Build-up'!L18*Assumptions!L33 -> 13239.763 | M18: ='Revenue Build-up'!M18*Assumptions!M33 -> 14709.414 | N18: ='Revenue Build-up'!N18*Assumptions!N33 -> 16143.072 | O18: ='Revenue Build-up'!O18*Assumptions!O33 -> 18150.413 | P18: ='Revenue Build-up'!P18*Assumptions!P33 -> 19368.986
C19: [+] Deferred Revenue (Current) | E19: $M | G19: 1447 | H19: 1747 | I19: 2864 | J19: 3168 | K19: 3424 | L19: ='Revenue Build-up'!L18*Assumptions!L34 -> 3564.5516 | M19: ='Revenue Build-up'!M18*Assumptions!M34 -> 3960.2267 | N19: ='Revenue Build-up'!N18*Assumptions!N34 -> 4520.0602 | O19: ='Revenue Build-up'!O18*Assumptions!O34 -> 5082.1156 | P19: ='Revenue Build-up'!P18*Assumptions!P34 -> 5649.2875
C20: [+] Current Portion of Debt | E20: $M | G20: 1589 | H20: 1502 | I20: 2373 | J20: 2456 | K20: 1640 | L20: =K20 -> 1640 | M20: =L20 -> 1640 | N20: =M20 -> 1640 | O20: =N20 -> 1640 | P20: =O20 -> 1640
C21: Total Current Liabilities | E21: $M | G21: =SUM(G17:G20) -> 19705 | H21: =SUM(H17:H20) -> 26709 | I21: =SUM(I17:I20) -> 28748 | J21: =SUM(J17:J20) -> 28821 | K21: =SUM(K17:K20) -> 31714 | L21: =SUM(L17:L20) -> 32318.1 | M21: =SUM(M17:M20) -> 35493.106 | N21: =SUM(N17:N20) -> 38837.521 | ... P21: =SUM(P17:P20) -> 46892.082
C23: Long-Term Debt | E23: $M | G23: 5245 | H23: 1597 | I23: 2857 | J23: 5757 | K23: 6736 | L23: ='Loans & Other Income'!L8-L20 -> 6736 | M23: ='Loans & Other Income'!M8-M20 -> 6736 | N23: ='Loans & Other Income'!N8-N20 -> 6736 | O23: ='Loans & Other Income'!O8-O20 -> 6736 | P23: ='Loans & Other Income'!P8-P20 -> 6736
C24: [+] Deferred Revenue (Non-Current) | E24: $M | G24: 2052 | H24: 2804 | I24: 3251 | J24: 3317 | K24: 3631 | L24: ='Revenue Build-up'!L18*Assumptions!L36 -> 3564.5516 | M24: ='Revenue Build-up'!M18*Assumptions!M36 -> 3960.2267 | N24: ='Revenue Build-up'!N18*Assumptions!N36 -> 4520.0602 | O24: ='Revenue Build-up'!O18*Assumptions!O36 -> 5082.1156 | P24: ='Revenue Build-up'!P18*Assumptions!P36 -> 5649.2875
C25: [+] Other Non-Current Liabilities | E25: $M | G25: 4114 | H25: 5739 | I25: 8395 | J25: 10558 | K25: 12860 | L25: ='Revenue Build-up'!L18*Assumptions!L38 -> 13239.763 | M25: ='Revenue Build-up'!M18*Assumptions!M38 -> 14143.667 | N25: ='Revenue Build-up'!N18*Assumptions!N38 -> 15497.349 | O25: ='Revenue Build-up'!O18*Assumptions!O38 -> 17424.396 | P25: ='Revenue Build-up'!P18*Assumptions!P38 -> 18561.945
C26: TOTAL LIABILITIES | E26: $M | G26: =G21+SUM(G23:G25) -> 31116 | H26: =H21+SUM(H23:H25) -> 36849 | I26: =I21+SUM(I23:I25) -> 43251 | J26: =J21+SUM(J23:J25) -> 48453 | K26: =K21+SUM(K23:K25) -> 54941 | L26: =L21+SUM(L23:L25) -> 55858.415 | M26: =M21+SUM(M23:M25) -> 60332.999 | N26: =N21+SUM(N23:N25) -> 65590.93 | ... P26: =P21+SUM(P23:P25) -> 77839.314
A28: STOCKHOLDERS' EQUITY
C29: Common Stock & Additional Paid-in Capital | E29: $M | G29: 29806 | H29: 32180 | I29: 34895 | J29: 38374 | K29: 42773 | L29: =K29+'Equity Schedule'!L6 -> 46846.773 | M29: =L29+'Equity Schedule'!M6 -> 51372.747 | N29: =M29+'Equity Schedule'!N6 -> 56280.241 | O29: =N29+'Equity Schedule'!O6 -> 61797.966 | P29: =O29+'Equity Schedule'!P6 -> 67447.254
C30: [+] Accumulated Other Comprehensive Income | E30: $M | G30: 54 | H30: -361 | I30: -143 | J30: -670 | K30: 361 | L30: =K30 -> 361 | M30: =L30 -> 361 | N30: =M30 -> 361 | O30: =N30 -> 361 | P30: =O30 -> 361
C31: [+] Retained Earnings | E31: $M | G31: 329 | H31: 12885 | I31: 27882 | J31: 35209 | K31: 39003 | L31: =K31+IS!L43 -> 44514.925 | M31: =L31+IS!M43 -> 51920.912 | N31: =M31+IS!N43 -> 62339.924 | O31: =N31+IS!O43 -> 75815.622 | P31: =O31+IS!P43 -> 92216.997
C32: [+] Noncontrolling Interests | E32: $M | G32: 826 | H32: 785 | I32: 733 | J32: 704 | K32: 728 | L32: =K32 -> 728 | M32: =L32 -> 728 | N32: =M32 -> 728 | O32: =N32 -> 728 | P32: =O32 -> 728
C33: TOTAL EQUITY | E33: $M | G33: =SUM(G29:G32) -> 31015 | H33: =SUM(H29:H32) -> 45489 | I33: =SUM(I29:I32) -> 63367 | J33: =SUM(J29:J32) -> 73617 | K33: =SUM(K29:K32) -> 82865 | L33: =SUM(L29:L32) -> 92450.698 | M33: =SUM(M29:M32) -> 104382.66 | N33: =SUM(N29:N32) -> 119709.16 | ... P33: =SUM(P29:P32) -> 160753.25
C35: TOTAL LIABILITIES & EQUITY | E35: $M | G35: =G26+G33 -> 62131 | H35: =H26+H33 -> 82338 | I35: =I26+I33 -> 106618 | J35: =J26+J33 -> 122070 | K35: =K26+K33 -> 137806 | L35: =L26+L33 -> 148309.11 | M35: =M26+M33 -> 164715.66 | N35: =N26+N33 -> 185300.09 | ... P35: =P26+P33 -> 238592.56
C36: Balance Check (Assets − Liabilities & Equity) | G36: =G14-G35 -> 0 | H36: =H14-H35 -> 0 | I36: =I14-I35 -> 0 | J36: =J14-J35 -> 0 | K36: =K14-K35 -> 0 | L36: =L14-L35 -> 0 | M36: =M14-M35 -> 0 | N36: =N14-N35 -> 0 | ... P36: =P14-P35 -> 0
C37: Balance Check Status | G37: =IF(ABS(G36)<0.5,"PASS","FAIL") -> PASS | H37: =IF(ABS(H36)<0.5,"PASS","FAIL") -> PASS | I37: =IF(ABS(I36)<0.5,"PASS","FAIL") -> PASS | J37: =IF(ABS(J36)<0.5,"PASS","FAIL") -> PASS | K37: =IF(ABS(K36)<0.5,"PASS","FAIL") -> PASS | L37: =IF(ABS(L36)<0.5,"PASS","FAIL") -> PASS | M37: =IF(ABS(M36)<0.5,"PASS","FAIL") -> PASS | N37: =IF(ABS(N36)<0.5,"PASS","FAIL") -> PASS | ... P37: =IF(ABS(P36)<0.5,"PASS","FAIL") -> PASS

Sheet Asset Schedule
A1: TESLA, INC. | E1: ◄ Cover | G1: ASSET SCHEDULE
A2: USD millions except per-share and operating data
E3: Unit | G3: FY21A | H3: FY22A | I3: FY23A | J3: FY24A | K3: FY25A | L3: FY26E | M3: FY27E | N3: FY28E | O3: FY29E | P3: FY30E
A4: PROPERTY, PLANT & EQUIPMENT (NET)
C5: Opening Net PP&E | E5: $M | G5: 12747 | H5: =G9 -> 18884 | I5: =H9 -> 23548 | J5: =I9 -> 29725 | K5: =J9 -> 35836 | L5: =K9 -> 40643 | M5: =L9 -> 44121.338 | N5: =M9 -> 47811.111 | O5: =N9 -> 52023.4 | P5: =O9 -> 56562.171
C6: [+] Capital Expenditure | E6: $M | G6: 6482 | H6: 7158 | I6: 8899 | J6: 11342 | K6: 8527 | L6: ='Revenue Build-up'!L18*Assumptions!L41 -> 10184.433 | M6: ='Revenue Build-up'!M18*Assumptions!M41 -> 10749.187 | N6: ='Revenue Build-up'!N18*Assumptions!N41 -> 11623.012 | O6: ='Revenue Build-up'!O18*Assumptions!O41 -> 12342.281 | P6: ='Revenue Build-up'!P18*Assumptions!P41 -> 12912.657
C7: [-] Depreciation & Amortization | E7: $M | G7: 2911 | H7: 3747 | I7: 4667 | J7: 5368 | K7: 6148 | L7: =L5*Assumptions!L42 -> 6706.095 | M7: =M5*Assumptions!M42 -> 7059.4141 | N7: =N5*Assumptions!N42 -> 7410.7222 | O7: =O5*Assumptions!O42 -> 7803.5101 | P7: =P5*Assumptions!P42 -> 8484.3257
C8: [+/-] Other Adjustments, net (hist. only) | E8: $M | G8: =18884-G5-G6+G7 -> 2566 | H8: =23548-H5-H6+H7 -> 1253 | I8: =29725-I5-I6+I7 -> 1945 | J8: =35836-J5-J6+J7 -> 137 | K8: =40643-K5-K6+K7 -> 2428 | L8: 0 | M8: 0 | N8: 0 | O8: 0 | P8: 0
C9: Closing Net PP&E | E9: $M | G9: =G5+G6-G7+G8 -> 18884 | H9: =H5+H6-H7+H8 -> 23548 | I9: =I5+I6-I7+I8 -> 29725 | J9: =J5+J6-J7+J8 -> 35836 | K9: =K5+K6-K7+K8 -> 40643 | L9: =L5+L6-L7+L8 -> 44121.338 | M9: =M5+M6-M7+M8 -> 47811.111 | N9: =N5+N6-N7+N8 -> 52023.4 | ... P9: =P5+P6-P7+P8 -> 60990.503
C11: Depreciation Rate (% of Opening Net PP&E) | G11: =G7/G5 -> 0.22836746 | H11: =H7/H5 -> 0.19842194 | I11: =I7/I5 -> 0.19819093 | J11: =J7/J5 -> 0.18058873 | K11: =K7/K5 -> 0.17155933 | L11: =L7/L5 -> 0.165 | M11: =M7/M5 -> 0.16 | N11: =N7/N5 -> 0.155 | ... P11: =P7/P5 -> 0.15

Sheet Loans & Other Income
A1: TESLA, INC. | E1: ◄ Cover | G1: LOANS & OTHER INCOME
A2: USD millions except per-share and operating data
E3: Unit | G3: FY21A | H3: FY22A | I3: FY23A | J3: FY24A | K3: FY25A | L3: FY26E | M3: FY27E | N3: FY28E | O3: FY29E | P3: FY30E
A4: DEBT SCHEDULE
C5: Opening Total Debt (Current + Long-Term) | E5: $M | G5: 11688 | H5: =G8 -> 6834 | I5: =H8 -> 3099 | J5: =I8 -> 5230 | K5: =J8 -> 8213 | L5: =K8 -> 8376 | M5: =L8 -> 8376 | N5: =M8 -> 8376 | O5: =N8 -> 8376 | P5: =O8 -> 8376
C6: [+/-] Net Borrowings / (Repayments) | E6: $M | G6: -5284 | H6: -3364 | I6: 2580 | J6: 3244 | K6: 40 | L6: 0 | M6: 0 | N6: 0 | O6: 0 | P6: 0
C8: Closing Total Debt | E8: $M | G8: 6834 | H8: 3099 | I8: 5230 | J8: 8213 | K8: 8376 | L8: =L5+L6 -> 8376 | M8: =M5+M6 -> 8376 | N8: =N5+N6 -> 8376 | O8: =O5+O6 -> 8376 | P8: =P5+P6 -> 8376
C10: Effective Interest Rate on Debt | G10: =Assumptions!G45 -> 0.031741958 | H10: =Assumptions!H45 -> 0.027948493 | I10: =Assumptions!I45 -> 0.050338819 | J10: =Assumptions!J45 -> 0.066921606 | K10: =Assumptions!K45 -> 0.041154268 | L10: =Assumptions!L45 -> 0.05 | M10: =Assumptions!M45 -> 0.05 | N10: =Assumptions!N45 -> 0.05 | ... P10: =Assumptions!P45 -> 0.05
C11: Interest Expense | E11: $M | G11: 371 | H11: 191 | I11: 156 | J11: 350 | K11: 338 | L11: =AVERAGE(K8,L8)*L10 -> 418.8 | M11: =AVERAGE(L8,M8)*M10 -> 418.8 | N11: =AVERAGE(M8,N8)*N10 -> 418.8 | O11: =AVERAGE(N8,O8)*O10 -> 418.8 | P11: =AVERAGE(O8,P8)*P10 -> 418.8
A13: OTHER INCOME (RETURN ON CASH & INVESTMENTS)
C14: Cash & Short-Term Investments (interest-income basis) | E14: $M | G14: =AVERAGE(19384,BS!G5) -> 18480 | H14: =AVERAGE(BS!G5,BS!H5) -> 16914.5 | I14: =AVERAGE(BS!H5,BS!I5) -> 16325.5 | J14: =AVERAGE(BS!I5,BS!J5) -> 16268.5 | K14: =AVERAGE(BS!J5,BS!K5) -> 16326 | L14: =BS!K5 -> 16513 | M14: =BS!L5 -> 19640.666 | N14: =BS!M5 -> 23666.605 | O14: =BS!N5 -> 28247.664 | P14: =BS!O5 -> 35881.154
C15: Return Rate on Cash & Investments | G15: =Assumptions!G46 -> 0.003030303 | H15: =Assumptions!H46 -> 0.017558899 | I15: =Assumptions!I46 -> 0.065296622 | J15: =Assumptions!J46 -> 0.096444048 | K15: =Assumptions!K46 -> 0.10290334 | L15: =Assumptions!L46 -> 0.045 | M15: =Assumptions!M46 -> 0.045 | N15: =Assumptions!N46 -> 0.045 | ... P15: =Assumptions!P46 -> 0.04
C16: Interest Income | E16: $M | G16: 56 | H16: 297 | I16: 1066 | J16: 1569 | K16: 1680 | L16: =L14*L15 -> 743.085 | M16: =M14*M15 -> 883.82997 | N16: =N14*N15 -> 1064.9972 | O16: =O14*O15 -> 1129.9066 | P16: =P14*P15 -> 1435.2462

Sheet Tax Schedule
A1: TESLA, INC. | E1: ◄ Cover | G1: TAX SCHEDULE
A2: USD millions except per-share and operating data
E3: Unit | G3: FY21A | H3: FY22A | I3: FY23A | J3: FY24A | K3: FY25A | L3: FY26E | M3: FY27E | N3: FY28E | O3: FY29E | P3: FY30E
C4: PBT (Income Before Taxes) | E4: $M | G4: =IS!G37 -> 6343 | H4: =IS!H37 -> 13719 | I4: =IS!I37 -> 9973 | J4: =IS!J37 -> 8990 | K4: =IS!K37 -> 5278 | L4: =IS!L37 -> 7252.5328 | M4: =IS!M37 -> 9744.7203 | N4: =IS!N37 -> 13709.226 | ... P4: =IS!P37 -> 21580.756
C5: Effective / Normalized Tax Rate | G5: =G6/G4 -> 0.11020022 | H5: =H6/H4 -> 0.082513303 | I5: =I6/I4 -> -0.50145393 | J5: =J6/J4 -> 0.20433815 | K5: =K6/K4 -> 0.2696097 | L5: =Assumptions!L49 -> 0.24 | M5: =Assumptions!M49 -> 0.24 | N5: =Assumptions!N49 -> 0.24 | O5: =Assumptions!O49 -> 0.24 | P5: =Assumptions!P49 -> 0.24
C6: Income Tax Expense | E6: $M | G6: 699 | H6: 1132 | I6: -5001 | J6: 1837 | K6: 1423 | L6: =L4*L5 -> 1740.6079 | M6: =M4*M5 -> 2338.7329 | N6: =N4*N5 -> 3290.2143 | O6: =O4*O5 -> 4255.4835 | P6: =P4*P5 -> 5179.3815
C7: Implied Effective Tax Rate % | G7: =G6/G4 -> 0.11020022 | H7: =H6/H4 -> 0.082513303 | I7: =I6/I4 -> -0.50145393 | J7: =J6/J4 -> 0.20433815 | K7: =K6/K4 -> 0.2696097 | L7: =L6/L4 -> 0.24 | M7: =M6/M4 -> 0.24 | N7: =N6/N4 -> 0.24 | ... P7: =P6/P4 -> 0.24

Sheet Equity Schedule
A1: TESLA, INC. | E1: ◄ Cover | G1: EQUITY SCHEDULE
A2: USD millions except per-share and operating data
E3: Unit | G3: FY21A | H3: FY22A | I3: FY23A | J3: FY24A | K3: FY25A | L3: FY26E | M3: FY27E | N3: FY28E | O3: FY29E | P3: FY30E
C4: Opening Total Equity | E4: $M | G4: 23730 | H4: =G9 -> 30931 | I4: =H9 -> 45436 | J4: =I9 -> 63291 | K4: =J9 -> 73367 | L4: =K9 -> 82676 | M4: =L9 -> 92261.698 | N4: =M9 -> 104193.66 | O4: =N9 -> 119520.16 | P4: =O9 -> 138513.59
C5: [+] Net Income | E5: $M | G5: =IS!G43 -> 5644 | H5: =IS!H43 -> 12587 | I5: =IS!I43 -> 14974 | J5: =IS!J43 -> 7153 | K5: =IS!K43 -> 3855 | L5: =IS!L43 -> 5511.925 | M5: =IS!M43 -> 7405.9874 | N5: =IS!N43 -> 10419.012 | ... P5: =IS!P43 -> 16401.375
